[2025-06-17T04:00:00.972+0000] {local_task_job_runner.py:120} INFO - ::group::Pre task execution logs
[2025-06-17T04:00:00.994+0000] {taskinstance.py:2076} INFO - Dependencies all met for dep_context=non-requeueable deps ti=<TaskInstance: clickhouse_metrics_checker.check_metrics_row_count scheduled__2025-06-17T03:00:00+00:00 [queued]>
[2025-06-17T04:00:01.002+0000] {taskinstance.py:2076} INFO - Dependencies all met for dep_context=requeueable deps ti=<TaskInstance: clickhouse_metrics_checker.check_metrics_row_count scheduled__2025-06-17T03:00:00+00:00 [queued]>
[2025-06-17T04:00:01.003+0000] {taskinstance.py:2306} INFO - Starting attempt 1 of 2
[2025-06-17T04:00:01.158+0000] {taskinstance.py:2330} INFO - Executing <Task(PythonOperator): check_metrics_row_count> on 2025-06-17 03:00:00+00:00
[2025-06-17T04:00:01.166+0000] {standard_task_runner.py:63} INFO - Started process 847 to run task
[2025-06-17T04:00:01.172+0000] {standard_task_runner.py:90} INFO - Running: ['***', 'tasks', 'run', 'clickhouse_metrics_checker', 'check_metrics_row_count', 'scheduled__2025-06-17T03:00:00+00:00', '--job-id', '39', '--raw', '--subdir', 'DAGS_FOLDER/odd_even_time.py', '--cfg-path', '/tmp/tmp3ccdzpgd']
[2025-06-17T04:00:01.177+0000] {standard_task_runner.py:91} INFO - Job 39: Subtask check_metrics_row_count
[2025-06-17T04:00:01.232+0000] {task_command.py:426} INFO - Running <TaskInstance: clickhouse_metrics_checker.check_metrics_row_count scheduled__2025-06-17T03:00:00+00:00 [running]> on host 55c70c467e94
[2025-06-17T04:00:01.314+0000] {taskinstance.py:2648} INFO - Exporting env vars: AIRFLOW_CTX_DAG_OWNER='***' AIRFLOW_CTX_DAG_ID='clickhouse_metrics_checker' AIRFLOW_CTX_TASK_ID='check_metrics_row_count' AIRFLOW_CTX_EXECUTION_DATE='2025-06-17T03:00:00+00:00' AIRFLOW_CTX_TRY_NUMBER='1' AIRFLOW_CTX_DAG_RUN_ID='scheduled__2025-06-17T03:00:00+00:00'
[2025-06-17T04:00:01.315+0000] {taskinstance.py:430} INFO - ::endgroup::
[2025-06-17T04:00:01.328+0000] {connectionpool.py:874} WARNING - Retrying (Retry(total=0, connect=None, read=None, redirect=0, status=None)) after connection broken by 'NameResolutionError("<urllib3.connection.HTTPConnection object at 0x7f47457558d0>: Failed to resolve 'clickhouse-server' ([Errno -3] Temporary failure in name resolution)")': /?
[2025-06-17T04:00:01.328+0000] {httpclient.py:466} WARNING - Unexpected Http Driver Exception
[2025-06-17T04:00:01.329+0000] {taskinstance.py:441} INFO - ::group::Post task execution logs
[2025-06-17T04:00:01.329+0000] {taskinstance.py:2905} ERROR - Task failed with exception
Traceback (most recent call last):
  File "/home/airflow/.local/lib/python3.10/site-packages/urllib3/connection.py", line 198, in _new_conn
    sock = connection.create_connection(
  File "/home/airflow/.local/lib/python3.10/site-packages/urllib3/util/connection.py", line 60, in create_connection
    for res in socket.getaddrinfo(host, port, family, socket.SOCK_STREAM):
  File "/usr/local/lib/python3.10/socket.py", line 955, in getaddrinfo
    for res in _socket.getaddrinfo(host, port, family, type, proto, flags):
socket.gaierror: [Errno -3] Temporary failure in name resolution

The above exception was the direct cause of the following exception:

Traceback (most recent call last):
  File "/home/airflow/.local/lib/python3.10/site-packages/urllib3/connectionpool.py", line 793, in urlopen
    response = self._make_request(
  File "/home/airflow/.local/lib/python3.10/site-packages/urllib3/connectionpool.py", line 496, in _make_request
    conn.request(
  File "/home/airflow/.local/lib/python3.10/site-packages/urllib3/connection.py", line 400, in request
    self.endheaders()
  File "/usr/local/lib/python3.10/http/client.py", line 1278, in endheaders
    self._send_output(message_body, encode_chunked=encode_chunked)
  File "/usr/local/lib/python3.10/http/client.py", line 1038, in _send_output
    self.send(msg)
  File "/usr/local/lib/python3.10/http/client.py", line 976, in send
    self.connect()
  File "/home/airflow/.local/lib/python3.10/site-packages/urllib3/connection.py", line 238, in connect
    self.sock = self._new_conn()
  File "/home/airflow/.local/lib/python3.10/site-packages/urllib3/connection.py", line 205, in _new_conn
    raise NameResolutionError(self.host, self, e) from e
urllib3.exceptions.NameResolutionError: <urllib3.connection.HTTPConnection object at 0x7f47457556c0>: Failed to resolve 'clickhouse-server' ([Errno -3] Temporary failure in name resolution)

The above exception was the direct cause of the following exception:

Traceback (most recent call last):
  File "/home/airflow/.local/lib/python3.10/site-packages/clickhouse_connect/driver/httpclient.py", line 456, in _raw_request
    response = self.http.request(method, url, **kwargs)
  File "/home/airflow/.local/lib/python3.10/site-packages/urllib3/_request_methods.py", line 144, in request
    return self.request_encode_body(
  File "/home/airflow/.local/lib/python3.10/site-packages/urllib3/_request_methods.py", line 279, in request_encode_body
    return self.urlopen(method, url, **extra_kw)
  File "/home/airflow/.local/lib/python3.10/site-packages/urllib3/poolmanager.py", line 444, in urlopen
    response = conn.urlopen(method, u.request_uri, **kw)
  File "/home/airflow/.local/lib/python3.10/site-packages/urllib3/connectionpool.py", line 877, in urlopen
    return self.urlopen(
  File "/home/airflow/.local/lib/python3.10/site-packages/urllib3/connectionpool.py", line 847, in urlopen
    retries = retries.increment(
  File "/home/airflow/.local/lib/python3.10/site-packages/urllib3/util/retry.py", line 515, in increment
    raise MaxRetryError(_pool, url, reason) from reason  # type: ignore[arg-type]
urllib3.exceptions.MaxRetryError: HTTPConnectionPool(host='clickhouse-server', port=8123): Max retries exceeded with url: /? (Caused by NameResolutionError("<urllib3.connection.HTTPConnection object at 0x7f47457556c0>: Failed to resolve 'clickhouse-server' ([Errno -3] Temporary failure in name resolution)"))

The above exception was the direct cause of the following exception:

Traceback (most recent call last):
  File "/home/airflow/.local/lib/python3.10/site-packages/airflow/models/taskinstance.py", line 465, in _execute_task
    result = _execute_callable(context=context, **execute_callable_kwargs)
  File "/home/airflow/.local/lib/python3.10/site-packages/airflow/models/taskinstance.py", line 432, in _execute_callable
    return execute_callable(context=context, **execute_callable_kwargs)
  File "/home/airflow/.local/lib/python3.10/site-packages/airflow/models/baseoperator.py", line 400, in wrapper
    return func(self, *args, **kwargs)
  File "/home/airflow/.local/lib/python3.10/site-packages/airflow/operators/python.py", line 235, in execute
    return_value = self.execute_callable()
  File "/home/airflow/.local/lib/python3.10/site-packages/airflow/operators/python.py", line 252, in execute_callable
    return self.python_callable(*self.op_args, **self.op_kwargs)
  File "/opt/airflow/dags/odd_even_time.py", line 13, in query_clickhouse
    client = clickhouse_connect.get_client(
  File "/home/airflow/.local/lib/python3.10/site-packages/clickhouse_connect/driver/__init__.py", line 122, in create_client
    return HttpClient(interface, host, port, username, password, database, access_token,
  File "/home/airflow/.local/lib/python3.10/site-packages/clickhouse_connect/driver/httpclient.py", line 165, in __init__
    super().__init__(database=database,
  File "/home/airflow/.local/lib/python3.10/site-packages/clickhouse_connect/driver/client.py", line 70, in __init__
    self._init_common_settings(apply_server_timezone)
  File "/home/airflow/.local/lib/python3.10/site-packages/clickhouse_connect/driver/client.py", line 75, in _init_common_settings
    tuple(self.command('SELECT version(), timezone()', use_database=False))
  File "/home/airflow/.local/lib/python3.10/site-packages/clickhouse_connect/driver/httpclient.py", line 368, in command
    response = self._raw_request(payload, params, headers, method, fields=fields, server_wait=False)
  File "/home/airflow/.local/lib/python3.10/site-packages/clickhouse_connect/driver/httpclient.py", line 468, in _raw_request
    raise OperationalError(f'Error {ex} executing HTTP request attempt {attempts}{err_url}') from ex
clickhouse_connect.driver.exceptions.OperationalError: Error HTTPConnectionPool(host='clickhouse-server', port=8123): Max retries exceeded with url: /? (Caused by NameResolutionError("<urllib3.connection.HTTPConnection object at 0x7f47457556c0>: Failed to resolve 'clickhouse-server' ([Errno -3] Temporary failure in name resolution)")) executing HTTP request attempt 1 (http://clickhouse-server:8123)
[2025-06-17T04:00:01.339+0000] {taskinstance.py:1206} INFO - Marking task as UP_FOR_RETRY. dag_id=clickhouse_metrics_checker, task_id=check_metrics_row_count, run_id=scheduled__2025-06-17T03:00:00+00:00, execution_date=20250617T030000, start_date=20250617T040000, end_date=20250617T040001
[2025-06-17T04:00:01.349+0000] {standard_task_runner.py:110} ERROR - Failed to execute job 39 for task check_metrics_row_count (Error HTTPConnectionPool(host='clickhouse-server', port=8123): Max retries exceeded with url: /? (Caused by NameResolutionError("<urllib3.connection.HTTPConnection object at 0x7f47457556c0>: Failed to resolve 'clickhouse-server' ([Errno -3] Temporary failure in name resolution)")) executing HTTP request attempt 1 (http://clickhouse-server:8123); 847)
[2025-06-17T04:00:01.381+0000] {local_task_job_runner.py:240} INFO - Task exited with return code 1
[2025-06-17T04:00:01.410+0000] {taskinstance.py:3498} INFO - 0 downstream tasks scheduled from follow-on schedule check
[2025-06-17T04:00:01.412+0000] {local_task_job_runner.py:222} INFO - ::endgroup::
